Workbook
Name _meses: OFFSET(SUELDOS!XER1048551,SUELDOS!$K$28,0,SUELDOS!$K$29,1)
Name _sueldo: OFFSET(SUELDOS!$H$3,[1]DOS!$K$28,0,SUELDOS!$K$29,1)

Sheet HORARIOS DE CONSULTAS Y CX
A1: HORARIOS DE CONSULTAS Y PROCEDIMIENTOS EN LAS CLINICAS
B2: LUNES | C2: MARTES | D2: MIERCOLES | E2: JUEVES | F2: VIERNES | G2: OBSERVACION
A3: 8-10 AM | B3: COROMINAS | C3: Marvesa | D3: INTEGRAL 3 | E3: INTEGRAL 3
A4: 10-12 AM | E4: GRUMED
A5: 2-4 PM | B5: Marvesa | C5: HCFFAA | D5: MARVESA | E5: HCFFAA | F5: HCFFAA
A6: 4-6 PM | B6: GMSM | C6: HMNSA | D6: GMSM | E6: GMSM | F6: HMNSA
B11: DIA DE CIRUGIA GMSM
B12: DIA DE CIRUGIA GRUMED
B13: DIA DE CIRUGIA MONUMENTAL Y/O INTEGRAL 3
B14: AYUDANTIA EN LA INTEGRAL A PAULINO
A18: HORARIOS DE CONSULTAS Y PROCEDIMIENTOS EN LOS HOSPITALES
B19: LUNES | C19: MARTES | D19: MIERCOLES | E19: JUEVES | F19: VIERNES | G19: OBSERVACION
A20: 7-10 AM | C20: MARVESA
A21: 10-12 AM | C21: MARVESA
A22: 1-4 PM | B22: MARVESA | C22: HCFF | D22: MARVESA | E22: HCFF | F22: HCFF
A23: 4-6 PM | B23: MHMNSA | C23: HMNSA | D23: HMNSA | E23: HMNSA | F23: HCFF
B28: DIA DE CONSUTA
B29: DIA DE CIRUGIA
B30: VISITA EN SALA Y/O CIRUGIA

Sheet consolidacion de pago bien 
A1: FECHA | B1: ARS | C1: RNC | D1: MONTO FACTURADO | E1: MONTO RETENIDO(RENTA) | F1: TOTAL A PAGAR | G1: FECHA DE ENTREGA | H1: FECHA DE PAGO | I1: Estatus | J1: OBSERVACIONES
A2: 44382 | B2: SENASA | C2: B1500000156 | D2: 12300 | E2: 1230 | F2: 11070 | G2: 44383 | H2: 10-12/AGOSTO | I2: Pagada
A3: 44382 | B3: HUMANO | C3: B0100000060 | D3: 8640 | E3: 864 | F3: 7776 | G3: 44382 | H3: 44413 | I3: Pagada
A4: 44382 | B4: MAPFRE | C4: B0100000062 | D4: 31170 | E4: 3117 | F4: =+D4-E4 -> 28053 | G4: 44384 | H4: 44428 | I4: Pagada
A5: 44382 | B5: P-HUMANO | C5: B01000000059 | D5: 1445 | E5: 144.5 | F5: =+D5-E5 -> 1300.5 | G5: 44382 | H5: 44413 | I5: Pagada
A6: 44382 | B6: SEMMA | C6: B0100000058 | D6: 10000 | E6: 1000 | F6: 9000 | G6: 44384 | H6: 44440 | I6: Pagada
A7: 44382 | B7: UNIVERSAL | C7: B0100000061 | D7: 4717.5 | E7: 471.75 | F7: =+D7-E7 -> 4245.75 | G7: 44382 | H7: 44413 | I7: Pagada
A8: 44413 | B8: SENASA | C8: B1500000157 | D8: 224460 | E8: =+D8*10% -> 22446 | F8: =+D8-E8 -> 202014 | G8: 44412 | H8: 10-12/septiembre | I8: Pagada
A9: 44413 | B9: HUMANO | C9: B0100000067 | D9: 14208.75 | E9: =+D9*10% -> 1420.875 | F9: =+D9-E9 -> 12787.875 | G9: 44412 | H9: 44444 | I9: Pagada
A10: 44413 | B10: MAPFRE | C10: B0100000069 | D10: 47449.48 | E10: =+D10*10% -> 4744.948 | F10: =+D10-E10 -> 42704.532 | G10: 44412 | H10: 44459 | I10: Pagada
A11: 44413 | B11: P-HUMANO | C11: B01000000066 | D11: 30220 | E11: =+D11*10% -> 3022 | F11: =+D11-E11 -> 27198 | G11: 44320 | H11: 44444 | I11: Pagada
A12: 44413 | B12: SEMMA | C12: B0100000065 | D12: 9100 | E12: =+D12*10% -> 910 | F12: =+D12-E12 -> 8190 | G12: 44412 | H12: 10-12/septiembre | I12: Pagada
A13: 44413 | B13: UNIVERSAL | C13: B0100000068 | D13: 43354 | E13: =+D13*10% -> 4335.4 | F13: =+D13-E13 -> 39018.6 | G13: 44412 | H13: 44444 | I13: Pagada
A14: 44444 | B14: SENASA | C14: B1500000158 | D14: 25780 | E14: =+D14*10% -> 2578 | F14: =+D14-E14 -> 23202 | G14: 44442 | H14: 10-12/OCTUBTE | I14: Pagada
A15: 44444 | B15: MAPFRE | C15: B0100000075 | D15: 8835 | E15: =+D15*10% -> 883.5 | F15: =+D15-E15 -> 7951.5 | G15: 44442 | H15: 44489 | I15: Pagada
A16: 44444 | B16: P-HUMANO | C16: B01000000073 | D16: 11790 | E16: =+D16*10% -> 1179 | F16: =+D16-E16 -> 10611 | G16: 44442 | H16: 44474 | I16: Pagada
A17: 44444 | B17: SEMMA | C17: B0100000072 | D17: 17500 | E17: =+D17*10% -> 1750 | F17: =+D17-E17 -> 15750 | G17: 44442 | H17: 10-12/OCTUBTE | I17: Pagada
A18: 44444 | B18: UNIVERSAL | C18: B0100000074 | D18: 87730.16 | E18: =+D18*10% -> 8773.016 | F18: =+D18-E18 -> 78957.144 | G18: 44442 | H18: 44474 | I18: Pagada
A19: 44444 | B19: GMA | C19: B0100000070 | D19: 10464 | E19: =+D19*10% -> 1046.4 | F19: =+D19-E19 -> 9417.6 | G19: 44442 | H19: 44479 | I19: Pagada
A20: 44444 | B20: FUTURO | C20: B0100000077 | D20: 4037 | E20: =+D20*10% -> 403.7 | F20: =+D20-E20 -> 3633.3 | G20: 44442 | H20: 44479 | I20: Pagada
A21: 44444 | B21: Yunen | C21: B0100000076 | D21: 8230 | E21: =+D21*10% -> 823 | F21: =+D21-E21 -> 7407 | G21: 44442 | H21: 44479 | I21: Pagada
A22: 44444 | B22: RENACER | C22: B0100000078 | D22: 9500 | E22: =+D22*10% -> 950 | F22: =+D22-E22 -> 8550 | G22: 44442 | H22: 44479 | I22: Pagada | J22: cta BHD-LEON
A23: 44444 | B23: YUNEN | C23: B0100000063 | D23: 32815 | E23: =+D23*10% -> 3281.5 | F23: =+D23-E23 -> 29533.5 | G23: 44383 | H23: 44479 | I23: Pagada
A24: 44474 | B24: SENASA | C24: B1500000159 | D24: 54765 | E24: =+D24*10% -> 5476.5 | F24: =+D24-E24 -> 49288.5 | G24: 44473 | H24: 10-12/NOV | I24: Pagada
A25: 44474 | B25: RENACER | C25: B0100000079 | D25: 2025 | E25: =+D25*10% -> 202.5 | F25: =+D25-E25 -> 1822.5 | G25: 04/102021 | H25: 44510 | I25: Pagada
A26: 44474 | B26: APS | C26: B0100000080 | D26: 5500 | E26: =+D26*10% -> 550 | F26: =+D26-E26 -> 4950 | G26: 44473 | H26: 44520 | I26: Pagada
A27: 44474 | B27: P-HUMANO | C27: B01000000081 | D27: 9532.5 | E27: =+D27*10% -> 953.25 | F27: =+D27-E27 -> 8579.25 | G27: 44473 | H27: 44505 | I27: Pagada
A28: 44474 | B28: HUMANO | C28: B0100000082 | D28: 1000 | E28: =+D28*10% -> 100 | F28: =+D28-E28 -> 900 | G28: 44473 | H28: 44505 | I28: Pagada
A29: 44474 | B29: ASEMAP | C29: B0100000083 | D29: 15500 | E29: =+D29*10% -> 1550 | F29: =+D29-E29 -> 13950 | G29: 44473 | H29: 44505 | I29: Pagada
A30: 44474 | B30: MAPFRE | C30: B0100000084 | D30: 7667.5 | E30: =+D30*10% -> 766.75 | F30: =+D30-E30 -> 6900.75 | G30: 44473 | H30: 44520 | I30: Pagada
A31: 44474 | B31: FUTURO | C31: B0100000085 | D31: 32697.5 | E31: =+D31*10% -> 3269.75 | F31: =+D31-E31 -> 29427.75 | G31: 44473 | H31: 44510 | I31: Pagada
A32: 44474 | B32: Yunen | C32: B0100000086 | D32: 2000 | E32: =+D32*10% -> 200 | F32: =+D32-E32 -> 1800 | G32: 44473 | H32: 44510 | I32: Pagada
A33: 44474 | B33: UNIVERSAL | C33: B0100000087 | D33: 2892.46 | E33: =+D33*10% -> 289.246 | F33: =+D33-E33 -> 2603.214 | G33: 44473 | H33: 44505 | I33: Pagada
A34: 44474 | B34: MONUMENTAL | C34: B0100000088 | D34: 3650 | E34: =+D34*10% -> 365 | F34: =+D34-E34 -> 3285 | G34: 44473 | H34: 44510 | I34: Pagada
A35: 44505 | B35: SENASA | C35: B1500000160 | D35: 72975 | E35: =+D35*10% -> 7297.5 | F35: =+D35-E35 -> 65677.5 | G35: 44503 | H35: 10-12/disc | I35: Pagada
A36: 44505 | B36: P-HUMANO | C36: B01000000089 | D36: 5930 | E36: =+D36*10% -> 593 | F36: =+D36-E36 -> 5337 | G36: 44503 | H36: 44535 | I36: Pagada
A37: 44505 | B37: MAPFRE | C37: B0100000090 | D37: 30550 | E37: =+D37*10% -> 3055 | F37: =+D37-E37 -> 27495 | G37: 44503 | H37: 44550 | I37: Pagada
A38: 44505 | B38: RENACER | C38: B0100000091 | D38: 2430 | E38: =+D38*10% -> 243 | F38: =+D38-E38 -> 2187 | G38: 043/112021 | H38: 44540 | I38: Pagada
A39: 44505 | B39: RESERVAS | C39: B0100000092 | D39: 1900 | E39: =+D39*10% -> 190 | F39: =+D39-E39 -> 1710 | G39: 44503 | H39: 44540 | I39: Pagada
A40: 44535 | B40: SENASA | C40: B1500000161 | D40: 7533.39 | E40: =+D40*10% -> 753.339 | F40: =+D40-E40 -> 6780.051 | G40: 44532 | H40: 10-12/enero | I40: Pagada
...

Sheet CONSOLIDADOS DE PAGOS
A1: CONSOLIDADOS DE PAGOS POR ARS
A2: ARS | B2: RNC | C2: MONTO FACTURADO | D2: MONTO RETENIDO(RENTA) | E2: TOTAL A PAGAR | F2: FECHA DE ENTREGA | G2: FECHA DE PAGO | H2: OBSERVACIONES
A3: SENASA | B3: B1500000156 | C3: 12300 | D3: 1230 | E3: 11070 | F3: 44383 | G3: 10-12/AGOSTO
A4: HUMANO | B4: B0100000060 | C4: 8640 | D4: 864 | E4: 7776 | F4: 44382 | G4: 44413 | L4: ENCABEZADO
A5: MAPFRE | B5: B0100000062 | C5: 31170 | D5: 3117 | E5: =+C5-D5 -> 28053 | F5: 44384 | G5: 44428 | L5: FACTURA PENDIENTE POR PAGO
A6: P-HUMANO | B6: B01000000059 | C6: 1445 | D6: 144.5 | E6: =+C6-D6 -> 1300.5 | F6: 44382 | G6: 44413 | L6: FACTURA DEVUELTA
A7: SEMMA | B7: B0100000058 | C7: 10000 | D7: 1000 | E7: 9000 | F7: 44384 | G7: 44440 | L7: FACTURA PAGADA
A8: UNIVERSAL | B8: B0100000061 | C8: 4717.5 | D8: 471.75 | E8: =+C8-D8 -> 4245.75 | F8: 44382 | G8: 44413
A9: TOTAL | C9: =SUM(C3:C8) -> 68272.5 | D9: =SUM(D3:D8) -> 6827.25 | E9: =SUM(E3:E8) -> 61445.25
C11: Mes de Julio-Agosto | G11: 2
A12: ARS | B12: RNC | C12: MONTO FACTURADO | D12: MONTO RETENIDO(RENTA) | E12: TOTAL A PAGAR | F12: FECHA DE ENTREGA | G12: FECHA DE PAGO | H12: OBSERVACIONES
A13: SENASA | B13: B1500000157 | C13: 224460 | D13: =+C13*10% -> 22446 | E13: =+C13-D13 -> 202014 | F13: 44412 | G13: 10-12/septiembre
A14: HUMANO | B14: B0100000067 | C14: 14208.75 | D14: =+C14*10% -> 1420.875 | E14: =+C14-D14 -> 12787.875 | F14: 44412 | G14: 44444
A15: MAPFRE | B15: B0100000069 | C15: 47449.48 | D15: =+C15*10% -> 4744.948 | E15: =+C15-D15 -> 42704.532 | F15: 44412 | G15: 44459
A16: P-HUMANO | B16: B01000000066 | C16: 30220 | D16: =+C16*10% -> 3022 | E16: =+C16-D16 -> 27198 | F16: 44320 | G16: 44444
A17: SEMMA | B17: B0100000065 | C17: 9100 | D17: =+C17*10% -> 910 | E17: =+C17-D17 -> 8190 | F17: 44412 | G17: 10-12/septiembre
A18: UNIVERSAL | B18: B0100000068 | C18: 43354 | D18: =+C18*10% -> 4335.4 | E18: =+C18-D18 -> 39018.6 | F18: 44412 | G18: 44444
A19: TOTAL | C19: =SUM(C13:C18) -> 368792.23 | D19: =SUM(D13:D18) -> 36879.223 | E19: =SUM(E13:E18) -> 331913.01
C21: MES AGOSTO-SEPTIEMBRE
A23: ARS | B23: RNC | C23: MONTO FACTURADO | D23: MONTO RETENIDO(RENTA) | E23: TOTAL A PAGAR | F23: FECHA DE ENTREGA | G23: FECHA DE PAGO | H23: OBSERVACIONES
A24: SENASA | B24: B1500000158 | C24: 25780 | D24: =+C24*10% -> 2578 | E24: =+C24-D24 -> 23202 | F24: 44442 | G24: 10-12/OCTUBTE
A25: MAPFRE | B25: B0100000075 | C25: 8835 | D25: =+C25*10% -> 883.5 | E25: =+C25-D25 -> 7951.5 | F25: 44442 | G25: 44489
A26: P-HUMANO | B26: B01000000073 | C26: 11790 | D26: =+C26*10% -> 1179 | E26: =+C26-D26 -> 10611 | F26: 44442 | G26: 44474
A27: SEMMA | B27: B0100000072 | C27: 17500 | D27: =+C27*10% -> 1750 | E27: =+C27-D27 -> 15750 | F27: 44442 | G27: 10-12/OCTUBTE
A28: UNIVERSAL | B28: B0100000074 | C28: 87730.16 | D28: =+C28*10% -> 8773.016 | E28: =+C28-D28 -> 78957.144 | F28: 44442 | G28: 44474
A29: GMA | B29: B0100000070 | C29: 10464 | D29: =+C29*10% -> 1046.4 | E29: =+C29-D29 -> 9417.6 | F29: 44442 | G29: 44479
A30: FUTURO | B30: B0100000077 | C30: 4037 | D30: =+C30*10% -> 403.7 | E30: =+C30-D30 -> 3633.3 | F30: 44442 | G30: 44479
A31: Yunen | B31: B0100000076 | C31: 8230 | D31: =+C31*10% -> 823 | E31: =+C31-D31 -> 7407 | F31: 44442 | G31: 44479
A32: RENACER | B32: B0100000078 | C32: 9500 | D32: =+C32*10% -> 950 | E32: =+C32-D32 -> 8550 | F32: 44442 | G32: 44479 | H32: cta BHD-LEON
A33: YUNEN | B33: B0100000063 | C33: 32815 | D33: =+C33*10% -> 3281.5 | E33: =+C33-D33 -> 29533.5 | F33: 44383 | G33: 44479
A34: TOTAL | C34: =SUM(C24:C33) -> 216681.16 | D34: =SUM(D24:D33) -> 21668.116 | E34: =SUM(E24:E33) -> 195013.04
C40: MES SEPTIEMBRE-OCTUBRE 2021
A42: ARS | B42: RNC | C42: MONTO FACTURADO | D42: MONTO RETENIDO(RENTA) | E42: TOTAL A PAGAR | F42: FECHA DE ENTREGA | G42: FECHA DE PAGO | H42: OBSERVACIONES
A43: SENASA | B43: B1500000159 | C43: 54765 | D43: =+C43*10% -> 5476.5 | E43: =+C43-D43 -> 49288.5 | F43: 44473 | G43: 10-12/NOV
A44: RENACER | B44: B0100000079 | C44: 2025 | D44: =+C44*10% -> 202.5 | E44: =+C44-D44 -> 1822.5 | F44: 04/102021 | G44: 44510
A45: APS | B45: B0100000080 | C45: 5500 | D45: =+C45*10% -> 550 | E45: =+C45-D45 -> 4950 | F45: 44473 | G45: 44520
A46: P-HUMANO | B46: B01000000081 | C46: 9532.5 | D46: =+C46*10% -> 953.25 | E46: =+C46-D46 -> 8579.25 | F46: 44473 | G46: 44505
A47: HUMANO | B47: B0100000082 | C47: 1000 | D47: =+C47*10% -> 100 | E47: =+C47-D47 -> 900 | F47: 44473 | G47: 44505
A48: ASEMAP | B48: B0100000083 | C48: 15500 | D48: =+C48*10% -> 1550 | E48: =+C48-D48 -> 13950 | F48: 44473 | G48: 44505
A49: MAPFRE | B49: B0100000084 | C49: 7667.5 | D49: =+C49*10% -> 766.75 | E49: =+C49-D49 -> 6900.75 | F49: 44473 | G49: 44520
...

Sheet SUELDOS
B1: SUELDOS Y/O HONORARIOS PRIVADOS
A2: Año | B2: Mes | C2: ERD | D2: MARVESA | E2: HMNSA | F2: HONORARIOS | G2: CONSULTAS | H2: TOTAL DEL MES
A3: 2021 | B3: Julio | C3: 35925 | D3: 58466.92 | E3: 34954.57 | F3: 121000 | H3: =SUM(C3:F3) -> 250346.49
A4: 2021 | B4: Agosto | C4: 35925 | D4: 58466.92 | E4: 34954.57 | F4: =+'CONSOLIDADOS DE PAGOS'!E9 -> 61445.25 | H4: =SUM(C4:F4) -> 190791.74 | K4: Mes | L4: Total
A5: 2021 | B5: Septiembre | C5: 35925 | D5: 58466.92 | E5: 34954.57 | F5: 331913.01 | H5: =SUM(C5:F5) -> 461259.5 | K5: Enero | L5: 1349555.6
A6: 2021 | B6: Octubre | C6: 35925 | D6: 58466.92 | E6: 34954.57 | F6: =+'CONSOLIDADOS DE PAGOS'!E34 -> 195013.04 | H6: =SUM(C6:F6) -> 324359.53 | K6: Febrero | L6: 1189739.8
A7: 2021 | B7: Noviembre | C7: 26500 | D7: 58886.92 | E7: 57700 | F7: =+'CONSOLIDADOS DE PAGOS'!E54 -> 123506.96 | H7: =SUM(C7:F7) -> 266593.88 | K7: Marzo | L7: 1285348.1
A8: 2021 | B8: Diciembre | C8: 26500 | D8: 58466.92 | E8: 57700 | F8: =+'CONSOLIDADOS DE PAGOS'!E66 -> 102406.5 | H8: =SUM(C8:F8) -> 245073.42 | K8: Abril | L8: 1508792
A9: 2022 | B9: Enero | C9: 26500 | D9: 58889.87 | E9: 57365.93 | F9: =+'CONSOLIDADOS DE PAGOS'!E79 -> 80956.971 | H9: =SUM(C9:F9) -> 223712.77 | K9: Mayo | L9: 1348325.6
A10: 2022 | B10: Febrero | C10: 26500 | D10: 58886 | E10: 57365.93 | F10: =+'CONSOLIDADOS DE PAGOS'!E93 -> 75409.65 | H10: =SUM(C10:F10) -> 218161.58 | K10: Junio | L10: 1319047.3
A11: 2022 | B11: Marzo | C11: 71300 | D11: 74886 | E11: 57365.93 | F11: 129321 | H11: =+C11+D11+E11+F11 -> 332872.93 | K11: Julio | L11: 1387573.1
A12: 2022 | B12: Abril | C12: 72655.11 | D12: 58886 | E12: 57365.93 | F12: 169756.02 | H12: =SUM(C12:F12) -> 358663.06 | K12: Agosto | L12: 1875101.7
A13: 2022 | B13: Mayo | C13: 72655.11 | D13: 58886 | E13: 57365.93 | F13: 130658.4 | H13: =SUM(C13:F13) -> 319565.44 | K13: Septiembre | L13: 2714837.9
A14: 2022 | B14: Junio | C14: 72655.11 | D14: 58886 | E14: 57365.93 | F14: 39941.1 | H14: =SUM(C14:F14) -> 228848.14 | K14: Octubre | L14: 1852981.1
A15: 2022 | B15: Julio | C15: 72655.11 | D15: 58886 | E15: 57365.93 | F15: =+'CONSOLIDADOS DE PAGOS'!E177 -> 65691 | H15: =SUM(C15:F15) -> 254598.04 | K15: Noviembre | L15: 1789729.8
A16: 2022 | B16: Agosto | C16: 72655.11 | D16: 58886 | E16: 57365.93 | F16: =+'CONSOLIDADOS DE PAGOS'!E188 -> 246284.87 | H16: =SUM(C16:F16) -> 435191.91 | K16: Diciembre | L16: 1566250.6
A17: 2022 | B17: Septiembre | C17: 72655.11 | D17: 58886 | E17: 57365.93 | F17: =+'CONSOLIDADOS DE PAGOS'!E204 -> 829822.24 | H17: =SUM(C17:F17) -> 1018729.3
A18: 2022 | B18: Octubre | C18: 72655.11 | D18: 58886 | E18: 57365.93 | F18: =+'CONSOLIDADOS DE PAGOS'!E214 -> 200775.01 | H18: =SUM(C18:F18) -> 389682.05
A19: 2022 | B19: Noviembre | C19: 72655.11 | D19: 58886 | E19: 57365.93 | F19: =+'CONSOLIDADOS DE PAGOS'!E230 -> 308422.82 | H19: =SUM(C19:F19) -> 497329.86
A20: 2022 | B20: Diciembre | C20: 72655.11 | D20: 58886 | E20: 57365.93 | F20: =+'CONSOLIDADOS DE PAGOS'!E241 -> 309126.6 | H20: =SUM(C20:F20) -> 498033.64
A21: 2023 | B21: Enero | C21: 72655.11 | D21: 58889.87 | E21: 57365.93 | F21: 160148.53 | G21: 6000 | H21: =+C21+D21+E21+F21+G21 -> 355059.44
A22: 2023 | B22: Febrero | C22: 72655.11 | D22: 58886 | E22: 57365.93 | F22: =+'CONSOLIDADOS DE PAGOS'!E260 -> 23911.2 | G22: 30000 | H22: =+C22+D22+E22+F22+G22 -> 242818.24
A23: 2023 | B23: Marzo | C23: 72655.11 | D23: 58886 | E23: 57365.93 | F23: =+'CONSOLIDADOS DE PAGOS'!E270 -> 230489.53 | G23: 30000 | H23: =+C23+D23+E23+F23+G23 -> 449396.57
A24: 2023 | B24: Abril | C24: 72655.11 | D24: 58886 | E24: 57365.93 | F24: =+'CONSOLIDADOS DE PAGOS'!E281 -> 260954.33 | G24: 0 | H24: =+C24+D24+E24+F24+G24 -> 449861.36
A25: 2023 | B25: Mayo | C25: 72655.11 | D25: 58886 | E25: 57365.93 | F25: =+'CONSOLIDADOS DE PAGOS'!E290 -> 278545.14 | G25: 10000 | H25: =+C25+D25+E25+F25+G25 -> 477452.18
A26: 2023 | B26: Junio | C26: 72655.11 | D26: 58886 | E26: 57365.93 | F26: =+'CONSOLIDADOS DE PAGOS'!E305 -> 286613.1 | G26: 20000 | H26: =+C26+D26+E26+F26+G26 -> 495520.14
A27: 2023 | B27: Julio | C27: 72655.11 | D27: 58886 | E27: 57365.93 | F27: =+'CONSOLIDADOS DE PAGOS'!E316 -> 189596.16 | H27: =+C27+D27+E27+F27+G27 -> 378503.2
A28: 2023 | B28: Agosto | C28: 72655.11 | D28: 58886 | E28: 57365.93 | F28: ='CONSOLIDADOS DE PAGOS'!E329 -> 403213.05 | G28: 10000 | H28: =+C28+D28+E28+F28+G28 -> 602120.09 | J28: Desplazamiento | K28: 44 | O28: Meses | P28: Sueldo
A29: 2023 | B29: Septiembre | C29: 72655.11 | D29: 58886 | E29: 57365.93 | F29: =+'CONSOLIDADOS DE PAGOS'!E343 -> 372549.78 | G29: 20000 | H29: =+C29+D29+E29+F29+G29 -> 581456.82 | J29: Acercamiento | K29: 54 | O29: {=OFFSET(SUELDOS!B3,SUELDOS!K28,0,SUELDOS!K29,1)} -> Marzo | P29: {=OFFSET(SUELDOS!H3,SUELDOS!K28,0,SUELDOS!K29,1)} -> 314171.59
A30: 2023 | B30: Octubre | C30: 72655.11 | D30: 58886 | E30: 57365.93 | F30: =+'CONSOLIDADOS DE PAGOS'!E357 -> 208166.22 | G30: 5000 | H30: =+C30+D30+E30+F30+G30 -> 402073.26 | O30: Abril | P30: 230005.25
A31: 2023 | B31: Noviembre | C31: 89000 | D31: 58886 | E31: 57365.93 | F31: =+'CONSOLIDADOS DE PAGOS'!E364 -> 285923.55 | G31: 0 | H31: =+C31+D31+E31+F31+G31 -> 491175.48 | O31: Mayo | P31: 218550.29
A32: 2023 | B32: Diciembre | C32: 72655.11 | D32: 58886 | E32: 57365.93 | F32: =+'CONSOLIDADOS DE PAGOS'!E373 -> 193207.5 | G32: 0 | H32: =+C32+D32+E32+F32+G32 -> 382114.54 | O32: Junio | P32: 212893.48
A33: 2024 | B33: Enero | C33: 72655.11 | D33: 58889.87 | E33: 57365.93 | F33: =+'CONSOLIDADOS DE PAGOS'!E380 -> 369322.2 | G33: 2000 | H33: =+C33+D33+E33+F33+G33 -> 560233.11 | O33: Julio | P33: 256216.09
A34: 2024 | B34: Febrero | C34: 72655.11 | D34: 58886 | E34: 57365.93 | F34: =+'CONSOLIDADOS DE PAGOS'!E388 -> 255045.6 | H34: =+C34+D34+E34+F34+G34 -> 443952.64 | O34: Agosto | P34: 332299.39
A35: 2024 | B35: Marzo | C35: 72655.11 | D35: 58886 | E35: 57365.93 | F35: 0 | H35: =+C35+D35+E35+F35+G35 -> 188907.04 | O35: Septiembre | P35: 399297.18
A36: 2024 | B36: Abril | C36: 72655.11 | D36: 58886 | E36: 57365.93 | F36: =+'CONSOLIDADOS DE PAGOS'!E401 -> 281355.3 | H36: =+C36+D36+E36+F36+G36 -> 470262.34 | O36: Octubre | P36: 309713.89
A37: 2024 | B37: Mayo | C37: 72655.11 | D37: 58886 | E37: 57365.93 | F37: =+'CONSOLIDADOS DE PAGOS'!E412 -> 143850.6 | H37: =+C37+D37+E37+F37+G37 -> 332757.64 | O37: Noviembre | P37: 208550.29
A38: 2024 | B38: Junio | C38: 72655.11 | D38: 58886 | E38: 57365.93 | F38: =+'CONSOLIDADOS DE PAGOS'!E424 -> 197221.71 | H38: =+C38+D38+E38+F38+G38 -> 386128.75 | O38: Diciembre/doble | P38: 265588.72
A39: 2024 | B39: Julio | C39: 72655.11 | D39: 58886 | E39: 57365.93 | F39: =+'CONSOLIDADOS DE PAGOS'!E430 -> 106668 | H39: =+C39+D39+E39+F39+G39 -> 295575.04 | O39: Diciembre | P39: 220443.68
A40: 2024 | B40: Agosto | C40: 72655.11 | D40: 58886 | E40: 57365.93 | F40: =+'CONSOLIDADOS DE PAGOS'!E441 -> 249540.59 | H40: =+C40+D40+E40+F40+G40 -> 438447.63 | O40: Enero | P40: 354326.49
...

Sheet Dashboard Sueldos
A1: DASHBOARD DE SUELDOS Y HONORARIOS
A2: Período: Julio 2021 — Diciembre 2026 | Incluye Proyecciones | Fuente: Hoja SUELDOS
A4: TOTAL PAGADO (Histórico) | C4: PROMEDIO MENSUAL | E4: MES MÁS ALTO | G4: MES MÁS BAJO | I4: TOTAL ERD (Histórico) | K4: TOTAL HONORARIOS (Histórico) | M4: PROY. TOTAL 2026 | O4: VARIACIÓN 2025 vs 2024
A5: =SUM(SUELDOS!H3:H57) -> 19932433 | C5: =AVERAGE(SUELDOS!H3:H57) -> 362407.88 | E5: =MAX(SUELDOS!H3:H57) -> 1018729.3 | G5: =_xlfn.MINIFS(SUELDOS!H3:H57,SUELDOS!H3:H57,">0") -> 188907.04 | I5: =SUM(SUELDOS!C3:C57) -> 3834802.6 | K5: =SUM(SUELDOS!F3:F57) -> 9458518.3 | M5: {=SUMPRODUCT((SUELDOS!A3:A68=2026)*SUELDOS!H3:H68)} -> 2930536.4 | O5: {=SUMPRODUCT((SUELDOS!A3:A57=2025)*SUELDOS!H3:H57)/SUMPRODUCT((SUELDOS!A3:A57=2024)*SUELDOS!H3:H57)-1} -> -0.25492653
A7: RESUMEN ANUAL | J7: COMPOSICIÓN PROMEDIO DEL INGRESO MENSUAL | N7: GRÁFICO ANUAL | Q7: DESGLOSE ANUAL
A8: Año | B8: ERD | C8: MARVESA | D8: HMNSA | E8: Honorarios | F8: Consultas | G8: Total Año | H8: Var. vs Anterior | J8: Componente | K8: Promedio Mensual | L8: % del Total | N8: Año | O8: Total | Q8: Año | R8: ERD | S8: MARVESA | T8: HMNSA | U8: Honorarios
A9: 2021 | B9: {=SUMPRODUCT((SUELDOS!A$3:A$68=2021)*SUELDOS!C$3:C$68)} -> 196700 | C9: {=SUMPRODUCT((SUELDOS!A$3:A$68=2021)*SUELDOS!D$3:D$68)} -> 351221.52 | D9: {=SUMPRODUCT((SUELDOS!A$3:A$68=2021)*SUELDOS!E$3:E$68)} -> 255218.28 | E9: {=SUMPRODUCT((SUELDOS!A$3:A$68=2021)*SUELDOS!F$3:F$68)} -> 935284.77 | F9: {=SUMPRODUCT((SUELDOS!A$3:A$68=2021)*SUELDOS!G$3:G$68)} -> 0 | G9: {=SUMPRODUCT((SUELDOS!A$3:A$68=2021)*SUELDOS!H$3:H$68)} -> 1738424.6 | H9: — | J9: ERD | K9: =AVERAGE(SUELDOS!C$3:C$56) -> 69511.867 | L9: =K9/SUM(K$9:K$13) -> 0.18639814 | N9: =A9 -> 2021 | O9: =G9 -> 1738424.6 | Q9: =A9 -> 2021 | R9: =B9 -> 196700 | S9: =C9 -> 351221.52 | T9: =D9 -> 255218.28 | U9: =E9 -> 935284.77
A10: 2022 | B10: {=SUMPRODUCT((SUELDOS!A$3:A$68=2022)*SUELDOS!C$3:C$68)} -> 778195.99 | C10: {=SUMPRODUCT((SUELDOS!A$3:A$68=2022)*SUELDOS!D$3:D$68)} -> 722635.87 | D10: {=SUMPRODUCT((SUELDOS!A$3:A$68=2022)*SUELDOS!E$3:E$68)} -> 688391.16 | E10: {=SUMPRODUCT((SUELDOS!A$3:A$68=2022)*SUELDOS!F$3:F$68)} -> 2586165.7 | F10: {=SUMPRODUCT((SUELDOS!A$3:A$68=2022)*SUELDOS!G$3:G$68)} -> 0 | G10: {=SUMPRODUCT((SUELDOS!A$3:A$68=2022)*SUELDOS!H$3:H$68)} -> 4775388.7 | H10: =IF(G9=0,"—",G10/G9-1) -> 1.7469634 | J10: MARVESA | K10: =AVERAGE(SUELDOS!D$3:D$56) -> 60653.184 | L10: =K10/SUM(K$9:K$13) -> 0.16264332 | N10: =A10 -> 2022 | O10: =G10 -> 4775388.7 | Q10: =A10 -> 2022 | R10: =B10 -> 778195.99 | S10: =C10 -> 722635.87 | T10: =D10 -> 688391.16 | U10: =E10 -> 2586165.7
A11: 2023 | B11: {=SUMPRODUCT((SUELDOS!A$3:A$68=2023)*SUELDOS!C$3:C$68)} -> 888206.21 | C11: {=SUMPRODUCT((SUELDOS!A$3:A$68=2023)*SUELDOS!D$3:D$68)} -> 706635.87 | D11: {=SUMPRODUCT((SUELDOS!A$3:A$68=2023)*SUELDOS!E$3:E$68)} -> 688391.16 | E11: {=SUMPRODUCT((SUELDOS!A$3:A$68=2023)*SUELDOS!F$3:F$68)} -> 2893318.1 | F11: {=SUMPRODUCT((SUELDOS!A$3:A$68=2023)*SUELDOS!G$3:G$68)} -> 131000 | G11: {=SUMPRODUCT((SUELDOS!A$3:A$68=2023)*SUELDOS!H$3:H$68)} -> 5307551.3 | H11: =IF(G10=0,"—",G11/G10-1) -> 0.1114386 | J11: HMNSA | K11: =AVERAGE(SUELDOS!E$3:E$56) -> 57214.046 | L11: =K11/SUM(K$9:K$13) -> 0.15342117 | N11: =A11 -> 2023 | O11: =G11 -> 5307551.3 | Q11: =A11 -> 2023 | R11: =B11 -> 888206.21 | S11: =C11 -> 706635.87 | T11: =D11 -> 688391.16 | U11: =E11 -> 2893318.1
A12: 2024 | B12: {=SUMPRODUCT((SUELDOS!A$3:A$68=2024)*SUELDOS!C$3:C$68)} -> 888206.21 | C12: {=SUMPRODUCT((SUELDOS!A$3:A$68=2024)*SUELDOS!D$3:D$68)} -> 706635.87 | D12: {=SUMPRODUCT((SUELDOS!A$3:A$68=2024)*SUELDOS!E$3:E$68)} -> 688391.16 | E12: {=SUMPRODUCT((SUELDOS!A$3:A$68=2024)*SUELDOS!F$3:F$68)} -> 2362747.9 | F12: {=SUMPRODUCT((SUELDOS!A$3:A$68=2024)*SUELDOS!G$3:G$68)} -> 2000 | G12: {=SUMPRODUCT((SUELDOS!A$3:A$68=2024)*SUELDOS!H$3:H$68)} -> 4647981.2 | H12: =IF(G11=0,"—",G12/G11-1) -> -0.12427014 | J12: HONORARIOS | K12: =AVERAGE(SUELDOS!F$3:F$56) -> 175157.75 | L12: =K12/SUM(K$9:K$13) -> 0.46969071 | N12: =A12 -> 2024 | O12: =G12 -> 4647981.2 | Q12: =A12 -> 2024 | R12: =B12 -> 888206.21 | S12: =C12 -> 706635.87 | T12: =D12 -> 688391.16 | U12: =E12 -> 2362747.9
A13: 2025 | B13: {=SUMPRODUCT((SUELDOS!A$3:A$68=2025)*SUELDOS!C$3:C$68)} -> 1083494.2 | C13: {=SUMPRODUCT((SUELDOS!A$3:A$68=2025)*SUELDOS!D$3:D$68)} -> 859399.54 | D13: {=SUMPRODUCT((SUELDOS!A$3:A$68=2025)*SUELDOS!E$3:E$68)} -> 837191.83 | E13: {=SUMPRODUCT((SUELDOS!A$3:A$68=2025)*SUELDOS!F$3:F$68)} -> 681001.84 | F13: {=SUMPRODUCT((SUELDOS!A$3:A$68=2025)*SUELDOS!G$3:G$68)} -> 2000 | G13: {=SUMPRODUCT((SUELDOS!A$3:A$68=2025)*SUELDOS!H$3:H$68)} -> 3463087.4 | H13: =IF(G12=0,"—",G13/G12-1) -> -0.25492653 | J13: CONSULTAS | K13: =AVERAGE(SUELDOS!G$3:G$56) -> 10384.615 | L13: =K13/SUM(K$9:K$13) -> 0.027846656 | N13: =A13 -> 2025 | O13: =G13 -> 3463087.4 | Q13: =A13 -> 2025 | R13: =B13 -> 1083494.2 | S13: =C13 -> 859399.54 | T13: =D13 -> 837191.83 | U13: =E13 -> 681001.84
A14: 2026 | B14: {=SUMPRODUCT((SUELDOS!A$3:A$68=2026)*SUELDOS!C$3:C$68)} -> 892779.91 | C14: {=SUMPRODUCT((SUELDOS!A$3:A$68=2026)*SUELDOS!D$3:D$68)} -> 819452.54 | D14: {=SUMPRODUCT((SUELDOS!A$3:A$68=2026)*SUELDOS!E$3:E$68)} -> 778018.03 | E14: {=SUMPRODUCT((SUELDOS!A$3:A$68=2026)*SUELDOS!F$3:F$68)} -> 423285.9 | F14: {=SUMPRODUCT((SUELDOS!A$3:A$68=2026)*SUELDOS!G$3:G$68)} -> 17000 | G14: {=SUMPRODUCT((SUELDOS!A$3:A$68=2026)*SUELDOS!H$3:H$68)} -> 2930536.4 | H14: =IF(G13=0,"—",G14/G13-1) -> -0.15377927 | J14: TOTAL | K14: =SUM(K9:K13) -> 372921.46 | L14: =SUM(L9:L13) -> 1 | N14: =A14 -> 2026 | O14: =G14 -> 2930536.4 | Q14: =A14 -> 2026 | R14: =B14 -> 892779.91 | S14: =C14 -> 819452.54 | T14: =D14 -> 778018.03 | U14: =E14 -> 423285.9
A16: EVOLUCIÓN MENSUAL — HISTÓRICO + PROYECCIONES | J16: ANÁLISIS DE PROYECCIONES 2026 | N16: COMPOSICIÓN
A17: Período | B17: Salario Base | C17: Honorarios | D17: Consultas | E17: Total | J17: Concepto | K17: 2025 Real | L17: 2026 Proyectado | N17: Componente | O17: Promedio
A18: =SUELDOS!B3&" "&SUELDOS!A3 -> Julio 2021 | B18: =SUELDOS!C3+SUELDOS!D3+SUELDOS!E3 -> 129346.49 | C18: =SUELDOS!F3 -> 121000 | D18: =SUELDOS!G3 -> 0 | E18: =SUELDOS!H3 -> 250346.49 | J18: Salario Base (ERD+MARV+HMNSA) | K18: {=SUMPRODUCT((SUELDOS!A3:A57=2025)*(SUELDOS!C3:C57+SUELDOS!D3:D57+SUELDOS!E3:E57))} -> 2780085.6 | L18: {=SUMPRODUCT((SUELDOS!A3:A68=2026)*(SUELDOS!C3:C68+SUELDOS!D3:D68+SUELDOS!E3:E68))} -> 2490250.5 | N18: =J9 -> ERD | O18: =K9 -> 69511.867
A19: =SUELDOS!B4&" "&SUELDOS!A4 -> Agosto 2021 | B19: =SUELDOS!C4+SUELDOS!D4+SUELDOS!E4 -> 129346.49 | C19: =SUELDOS!F4 -> 61445.25 | D19: =SUELDOS!G4 -> 0 | E19: =SUELDOS!H4 -> 190791.74 | J19: Honorarios (ARS) | K19: {=SUMPRODUCT((SUELDOS!A3:A57=2025)*SUELDOS!F3:F57)} -> 681001.84 | L19: {=SUMPRODUCT((SUELDOS!A3:A68=2026)*SUELDOS!F3:F68)} -> 423285.9 | N19: =J10 -> MARVESA | O19: =K10 -> 60653.184
A20: =SUELDOS!B5&" "&SUELDOS!A5 -> Septiembre 2021 | B20: =SUELDOS!C5+SUELDOS!D5+SUELDOS!E5 -> 129346.49 | C20: =SUELDOS!F5 -> 331913.01 | D20: =SUELDOS!G5 -> 0 | E20: =SUELDOS!H5 -> 461259.5 | J20: Consultas | K20: {=SUMPRODUCT((SUELDOS!A3:A57=2025)*SUELDOS!G3:G57)} -> 2000 | L20: {=SUMPRODUCT((SUELDOS!A3:A68=2026)*SUELDOS!G3:G68)} -> 17000 | N20: =J11 -> HMNSA | O20: =K11 -> 57214.046
A21: =SUELDOS!B6&" "&SUELDOS!A6 -> Octubre 2021 | B21: =SUELDOS!C6+SUELDOS!D6+SUELDOS!E6 -> 129346.49 | C21: =SUELDOS!F6 -> 195013.04 | D21: =SUELDOS!G6 -> 0 | E21: =SUELDOS!H6 -> 324359.53 | J21: TOTAL | K21: {=SUMPRODUCT((SUELDOS!A3:A57=2025)*SUELDOS!H3:H57)} -> 3463087.4 | L21: {=SUMPRODUCT((SUELDOS!A3:A68=2026)*SUELDOS!H3:H68)} -> 2930536.4 | N21: =J12 -> HONORARIOS | O21: =K12 -> 175157.75
A22: =SUELDOS!B7&" "&SUELDOS!A7 -> Noviembre 2021 | B22: =SUELDOS!C7+SUELDOS!D7+SUELDOS!E7 -> 143086.92 | C22: =SUELDOS!F7 -> 123506.96 | D22: =SUELDOS!G7 -> 0 | E22: =SUELDOS!H7 -> 266593.88 | J22: Variación % (2026 vs 2025) | K22: ="" | L22: =L21/K21-1 -> -0.15377927 | N22: =J13 -> CONSULTAS | O22: =K13 -> 10384.615
A23: =SUELDOS!B8&" "&SUELDOS!A8 -> Diciembre 2021 | B23: =SUELDOS!C8+SUELDOS!D8+SUELDOS!E8 -> 142666.92 | C23: =SUELDOS!F8 -> 102406.5 | D23: =SUELDOS!G8 -> 0 | E23: =SUELDOS!H8 -> 245073.42
A24: =SUELDOS!B9&" "&SUELDOS!A9 -> Enero 2022 | B24: =SUELDOS!C9+SUELDOS!D9+SUELDOS!E9 -> 142755.8 | C24: =SUELDOS!F9 -> 80956.971 | D24: =SUELDOS!G9 -> 0 | E24: =SUELDOS!H9 -> 223712.77
A25: =SUELDOS!B10&" "&SUELDOS!A10 -> Febrero 2022 | B25: =SUELDOS!C10+SUELDOS!D10+SUELDOS!E10 -> 142751.93 | C25: =SUELDOS!F10 -> 75409.65 | D25: =SUELDOS!G10 -> 0 | E25: =SUELDOS!H10 -> 218161.58
A26: =SUELDOS!B11&" "&SUELDOS!A11 -> Marzo 2022 | B26: =SUELDOS!C11+SUELDOS!D11+SUELDOS!E11 -> 203551.93 | C26: =SUELDOS!F11 -> 129321 | D26: =SUELDOS!G11 -> 0 | E26: =SUELDOS!H11 -> 332872.93
A27: =SUELDOS!B12&" "&SUELDOS!A12 -> Abril 2022 | B27: =SUELDOS!C12+SUELDOS!D12+SUELDOS!E12 -> 188907.04 | C27: =SUELDOS!F12 -> 169756.02 | D27: =SUELDOS!G12 -> 0 | E27: =SUELDOS!H12 -> 358663.06
A28: =SUELDOS!B13&" "&SUELDOS!A13 -> Mayo 2022 | B28: =SUELDOS!C13+SUELDOS!D13+SUELDOS!E13 -> 188907.04 | C28: =SUELDOS!F13 -> 130658.4 | D28: =SUELDOS!G13 -> 0 | E28: =SUELDOS!H13 -> 319565.44
A29: =SUELDOS!B14&" "&SUELDOS!A14 -> Junio 2022 | B29: =SUELDOS!C14+SUELDOS!D14+SUELDOS!E14 -> 188907.04 | C29: =SUELDOS!F14 -> 39941.1 | D29: =SUELDOS!G14 -> 0 | E29: =SUELDOS!H14 -> 228848.14
A30: =SUELDOS!B15&" "&SUELDOS!A15 -> Julio 2022 | B30: =SUELDOS!C15+SUELDOS!D15+SUELDOS!E15 -> 188907.04 | C30: =SUELDOS!F15 -> 65691 | D30: =SUELDOS!G15 -> 0 | E30: =SUELDOS!H15 -> 254598.04
A31: =SUELDOS!B16&" "&SUELDOS!A16 -> Agosto 2022 | B31: =SUELDOS!C16+SUELDOS!D16+SUELDOS!E16 -> 188907.04 | C31: =SUELDOS!F16 -> 246284.87 | D31: =SUELDOS!G16 -> 0 | E31: =SUELDOS!H16 -> 435191.91
A32: =SUELDOS!B17&" "&SUELDOS!A17 -> Septiembre 2022 | B32: =SUELDOS!C17+SUELDOS!D17+SUELDOS!E17 -> 188907.04 | C32: =SUELDOS!F17 -> 829822.24 | D32: =SUELDOS!G17 -> 0 | E32: =SUELDOS!H17 -> 1018729.3
A33: =SUELDOS!B18&" "&SUELDOS!A18 -> Octubre 2022 | B33: =SUELDOS!C18+SUELDOS!D18+SUELDOS!E18 -> 188907.04 | C33: =SUELDOS!F18 -> 200775.01 | D33: =SUELDOS!G18 -> 0 | E33: =SUELDOS!H18 -> 389682.05
A34: =SUELDOS!B19&" "&SUELDOS!A19 -> Noviembre 2022 | B34: =SUELDOS!C19+SUELDOS!D19+SUELDOS!E19 -> 188907.04 | C34: =SUELDOS!F19 -> 308422.82 | D34: =SUELDOS!G19 -> 0 | E34: =SUELDOS!H19 -> 497329.86
... A71: =SUELDOS!B56&" "&SUELDOS!A56 -> Diciembre/doble 2025 | B71: =SUELDOS!C56+SUELDOS!D56+SUELDOS!E56 -> 265588.72 | C71: =SUELDOS!F56 -> 0 | D71: =SUELDOS!G56 -> 0 | E71: =SUELDOS!H56 -> 265588.72
A72: 📋 NOTAS Y HALLAZGOS CLAVE
A73: 1. | B73: SENASA fue la ARS más rentable en honorarios (61% del total de pagos ARS). El pico fue septiembre 2022 ($926K facturados).
A74: 2. | B74: Los salarios base (ERD+MARVESA+HMNSA) se incrementaron ~15% en 2025 vs 2024, pasando de $688K a $837K anuales para HMNSA.
A75: 3. | B75: Los honorarios por ARS son altamente volátiles — varían de $0 a $926K por mes, creando alta incertidumbre en el ingreso total.
A76: 4. | B76: 2023 fue el año pico de ingresos totales ($5.31M), impulsado por honorarios ARS consistentemente altos todo el año.
A77: 5. | B77: PROYECCIÓN 2026: Caída estimada de -23.2% vs 2025, principalmente porque los honorarios de Mar-Dic 2026 aún no tienen valores.
A78: 6. | B78: Las filas en AMARILLO (Mar-Dic 2026) representan proyecciones basadas solo en salario base fijo, sin honorarios estimados.
A79: 7. | B79: RIESGO CLAVE: Los honorarios representan ~47% del ingreso total promedio — alta dependencia de la facturación a aseguradoras.
...

Sheet Leyenda
B2: Columna1 | C2: Columna2 | E2: RNC | F2: Proveedor
B3: 1 | C3: GASTO DE PERSONAL | E3: 00100796911 | F3: Dr. Alejandro Soto Mendez
B4: 2 | C4: GASTOS POR TRABAJOS, SUMINISTROS Y SERVICIOS | E4: 00102420817 | F4: Manuel de Js. Sosa Sanchez
B5: 3 | C5: ARRENDAMIENTOS | E5: 01100286119 | F5: Lorenzo Ernesto Otaño Santiago
B6: 4 | C6: GASTOS DE ACTIVOS FIJO | E6: 401010062 | F6: Banco de Reservas de la República Dominicana Banco de Servicios Multiples//BanReservas
B7: 5 | C7: GASTOS DE REPRESENTACION | E7: 101136792 | F7: Banco Multiple BHD León, S. A.
B8: 6 | C8: OTRAS DEDUCCIONES ADMITIDAS | E8: 101010632 | F8: Banco Popular Dominicano, S. A. Banco Multiple
B9: 7 | C9: GASTOS FINANCIEROS | E9: 101043598 | F9: Banco Dominicano del Progreso, S. A.//Banco Multiple
B10: 8 | C10: GASTOS EXTRAORDINARIOS | E10: 101001577 | F10: CLARO//CODETEL
B11: 9 | C11: C.Y GTOS. QUE FORMAN PARTE DEL COSTO DE VENTA | E11: 101821248 | F11: EDESUR
B12: 10 | C12: ADQUISICIONES DE ACTIVOS | E12: 101502525 | F12: Tricom, S.A.
B13: 11 | C13: GASTOS DE SEGUROS | E13: 101019921 | F13: Centro Cuesta Nacional S.A.S.//Supermercados Nacional//Casa Cuesta//Ferretería Cuesta//JUMBO//Bebemundo
B14: 12 | C14: GASTOS MENORES | E14: 101796822 | F14: Grupo Ramos, S. A.//Super Pola//La Sirena
E15: 101793198 | F15: Mercatodo S.A.S.//Supermercados La Cadena
E16: 101602465 | F16: Bravo, S.A.//Supermercados Bravo
E17: 101035129 | F17: Supermercado El Dragon de Oro S. A.
E18: 101617871 | F18: El Cordel S.R.L.//Supermercado La Placita
E19: 101801875 | F19: Pricesmart Dominicana S. A.
E20: 101171111 | F20: Plaza Lama, S. A.
E21: 101532483 | F21: Hipermercados, Ole, S. A.
E22: 130265135 | F22: Inversiones Inmobiliarias E & D C. por A.//Supermercado Caribe
E23: 101600225 | F23: Comercial Gala, S.R.L. / Supermercado Gala
E24: 102000476 | F24: Daniel Espinal C. por A.//Farmax
E25: 101040302 | F25: Farmaco Quimica Nacional, S.A.//Farmaconal
E26: 101871865 | F26: Grupo Carol, S. A.//Farmacia Carol
... E118: 101819103 | F118: Centro EXPLORA de Educación Inicial, S.R.L.
E119: 22600032746 | F119: Jaime Velez Bello
E120: 00101133635 | F120: Hector Antonio Pereyra Espaillat//Pereyra Espaillat & Asocs.
E121: 07300002750 | F121: Maura Minaya
E122: 00101974616 | F122: Jenifer Duarte
E123: 00000000001 | F123: Bibiana Perez
E124: 00000000002 | F124: Delmaris Ramirez
E125: 00000000003 | F125: Dra. Martinez
E126: 00000000004 | F126: Mildred Jimenez
E127: 00000000005 | F127: Natalia Montero
E128: 130777871 | F128: Farmaland, S.R.L.
E129: 101605391 | F129: Hizpizza, S.R.L./Domino s Pizza
E130: 130060304 | F130: Tapas de Plata, S.R.L.
E131: 130950946 | F131: Farmacia del Parque, S.R.L.
... E315: 130652912 | F315: SUPER FARMACIA JOSE NEPO SRL
...

Sheet Gastos2024
A1: RNC o Cédula | B1: Tipo Id | C1: Tipo Bienes y Servicios Comprados | D1: Descripción | E1: NCF | F1: Fecha Comprobante | G1: Mes | H1: Dia | I1: Dia Semana | J1: Fecha | K1: Miembro Familia | L1: Producto | M1: Monto Facturado en Servicios | N1: Monto Facturado en Bienes | O1: Total Monto Facturado | P1: ITBIS Facturado | Q1: ITBIS Retenido | R1: Monto Propina Legal | S1: Forma de Pago | T1: Suplidor
A2: 430078549 | B2: 1 | C2: 12 | D2: =IF(C2=1,Leyenda!$C$3,IF(C2=2,Leyenda!$C$4,IF(C2=3,Leyenda!$C$5,IF(C2=4,Leyenda!$C$6,IF(C2=5,Leyenda!$C$7,IF(C2=6,Leyenda!$C$8,IF(C2=7,Leyenda!$C$9,IF(C2=8,Leyenda!$C$10," "))))))))&IF(C2=9,Leyenda!$C$11,IF(C2=10,Leyenda!$C$12,IF(C2=11,Leyenda!$C$13,IF(C2=12,Leyenda!$C$14," ")))) -> GASTOS MENORES | E2: 0 | F2: 45702 | G2: =TEXT(F2,"MMMM") -> febrero | H2: 14 | I2: =TEXT(gastos[[#This Row],[Fecha]],"DDDD") -> viernes | J2: =DATE(YEAR(F2),MONTH(F2),H2) -> 45702 | K2: Yahelis | L2: Seguimiento Odontologico Yahelis | M2: 1000 | N2: 0 | O2: =SUM(M2:N2) -> 1000 | P2: 0 | Q2: 0 | R2: 0 | S2: Tarjata de credito | T2: =IFERROR(VLOOKUP($A2,Tabla3[#All],2,0),"no esta registrado") -> Fundacion Cristiana de Consolacion y Ayuda
A3: 0 | B3: 1 | C3: 12 | D3: =IF(C3=1,Leyenda!$C$3,IF(C3=2,Leyenda!$C$4,IF(C3=3,Leyenda!$C$5,IF(C3=4,Leyenda!$C$6,IF(C3=5,Leyenda!$C$7,IF(C3=6,Leyenda!$C$8,IF(C3=7,Leyenda!$C$9,IF(C3=8,Leyenda!$C$10," "))))))))&IF(C3=9,Leyenda!$C$11,IF(C3=10,Leyenda!$C$12,IF(C3=11,Leyenda!$C$13,IF(C3=12,Leyenda!$C$14," ")))) -> GASTOS MENORES | E3: 0 | F3: 45745 | G3: =TEXT(F3,"MMMM") -> marzo | H3: 29 | I3: =TEXT(gastos[[#This Row],[Fecha]],"DDDD") -> sábado | J3: =DATE(YEAR(F3),MONTH(F3),H3) -> 45745 | K3: Andres | L3: Liga de baseball | M3: 2000 | N3: 0 | O3: =SUM(M3:N3) -> 2000 | P3: 0 | Q3: 0 | R3: 0 | S3: Transferencia bancaria | T3: =IFERROR(VLOOKUP($A3,Tabla3[#All],2,0),"no esta registrado") -> no esta registrado
A4: 0 | B4: 1 | C4: 12 | D4: =IF(C4=1,Leyenda!$C$3,IF(C4=2,Leyenda!$C$4,IF(C4=3,Leyenda!$C$5,IF(C4=4,Leyenda!$C$6,IF(C4=5,Leyenda!$C$7,IF(C4=6,Leyenda!$C$8,IF(C4=7,Leyenda!$C$9,IF(C4=8,Leyenda!$C$10," "))))))))&IF(C4=9,Leyenda!$C$11,IF(C4=10,Leyenda!$C$12,IF(C4=11,Leyenda!$C$13,IF(C4=12,Leyenda!$C$14," ")))) -> GASTOS MENORES | E4: 0 | F4: 45714 | G4: =TEXT(F4,"MMMM") -> febrero | H4: 29 | I4: =TEXT(gastos[[#This Row],[Fecha]],"DDDD") -> sábado | J4: =DATE(YEAR(F4),MONTH(F4),H4) -> 45717 | K4: Javier | L4: Liga de baseball | M4: 2000 | N4: 0 | O4: =SUM(M4:N4) -> 2000 | P4: 0 | Q4: 0 | R4: 0 | S4: Transferencia bancaria | T4: =IFERROR(VLOOKUP($A4,Tabla3[#All],2,0),"no esta registrado") -> no esta registrado
A5: 0 | B5: 1 | C5: 12 | D5: =IF(C5=1,Leyenda!$C$3,IF(C5=2,Leyenda!$C$4,IF(C5=3,Leyenda!$C$5,IF(C5=4,Leyenda!$C$6,IF(C5=5,Leyenda!$C$7,IF(C5=6,Leyenda!$C$8,IF(C5=7,Leyenda!$C$9,IF(C5=8,Leyenda!$C$10," "))))))))&IF(C5=9,Leyenda!$C$11,IF(C5=10,Leyenda!$C$12,IF(C5=11,Leyenda!$C$13,IF(C5=12,Leyenda!$C$14," ")))) -> GASTOS MENORES | E5: 0 | F5: 45714 | G5: =TEXT(F5,"MMMM") -> febrero | H5: 29 | I5: =TEXT(gastos[[#This Row],[Fecha]],"DDDD") -> sábado | J5: =DATE(YEAR(F5),MONTH(F5),H5) -> 45717 | K5: Andres | L5: Liga de baseball | M5: 2000 | N5: 0 | O5: =SUM(M5:N5) -> 2000 | P5: 0 | Q5: 0 | R5: 0 | S5: Transferencia bancaria | T5: =IFERROR(VLOOKUP($A5,Tabla3[#All],2,0),"no esta registrado") -> no esta registrado
A6: 0 | B6: 1 | C6: 12 | D6: =IF(C6=1,Leyenda!$C$3,IF(C6=2,Leyenda!$C$4,IF(C6=3,Leyenda!$C$5,IF(C6=4,Leyenda!$C$6,IF(C6=5,Leyenda!$C$7,IF(C6=6,Leyenda!$C$8,IF(C6=7,Leyenda!$C$9,IF(C6=8,Leyenda!$C$10," "))))))))&IF(C6=9,Leyenda!$C$11,IF(C6=10,Leyenda!$C$12,IF(C6=11,Leyenda!$C$13,IF(C6=12,Leyenda!$C$14," ")))) -> GASTOS MENORES | E6: 0 | F6: 45683 | G6: =TEXT(F6,"MMMM") -> enero | H6: 29 | I6: =TEXT(gastos[[#This Row],[Fecha]],"DDDD") -> miércoles | J6: =DATE(YEAR(F6),MONTH(F6),H6) -> 45686 | K6: Javier | L6: Liga de baseball | M6: 2000 | N6: 0 | O6: =SUM(M6:N6) -> 2000 | P6: 0 | Q6: 0 | R6: 0 | S6: Transferencia bancaria | T6: =IFERROR(VLOOKUP($A6,Tabla3[#All],2,0),"no esta registrado") -> no esta registrado
A7: 0 | B7: 1 | C7: 12 | D7: =IF(C7=1,Leyenda!$C$3,IF(C7=2,Leyenda!$C$4,IF(C7=3,Leyenda!$C$5,IF(C7=4,Leyenda!$C$6,IF(C7=5,Leyenda!$C$7,IF(C7=6,Leyenda!$C$8,IF(C7=7,Leyenda!$C$9,IF(C7=8,Leyenda!$C$10," "))))))))&IF(C7=9,Leyenda!$C$11,IF(C7=10,Leyenda!$C$12,IF(C7=11,Leyenda!$C$13,IF(C7=12,Leyenda!$C$14," ")))) -> GASTOS MENORES | E7: 0 | F7: 45683 | G7: =TEXT(F7,"MMMM") -> enero | H7: 29 | I7: =TEXT(gastos[[#This Row],[Fecha]],"DDDD") -> miércoles | J7: =DATE(YEAR(F7),MONTH(F7),H7) -> 45686 | K7: Andres | L7: Liga de baseball | M7: 2000 | N7: 0 | O7: =SUM(M7:N7) -> 2000 | P7: 0 | Q7: 0 | R7: 0 | S7: Transferencia bancaria | T7: =IFERROR(VLOOKUP($A7,Tabla3[#All],2,0),"no esta registrado") -> no esta registrado
A8: 0 | B8: 1 | C8: 12 | D8: =IF(C8=1,Leyenda!$C$3,IF(C8=2,Leyenda!$C$4,IF(C8=3,Leyenda!$C$5,IF(C8=4,Leyenda!$C$6,IF(C8=5,Leyenda!$C$7,IF(C8=6,Leyenda!$C$8,IF(C8=7,Leyenda!$C$9,IF(C8=8,Leyenda!$C$10," "))))))))&IF(C8=9,Leyenda!$C$11,IF(C8=10,Leyenda!$C$12,IF(C8=11,Leyenda!$C$13,IF(C8=12,Leyenda!$C$14," ")))) -> GASTOS MENORES | E8: 0 | F8: 45745 | G8: =TEXT(F8,"MMMM") -> marzo | H8: 29 | I8: =TEXT(gastos[[#This Row],[Fecha]],"DDDD") -> sábado | J8: =DATE(YEAR(F8),MONTH(F8),H8) -> 45745 | K8: Javier | L8: Liga de baseball | M8: 2000 | N8: 0 | O8: =SUM(M8:N8) -> 2000 | P8: 0 | Q8: 0 | R8: 0 | S8: Transferencia bancaria | T8: =IFERROR(VLOOKUP($A8,Tabla3[#All],2,0),"no esta registrado") -> no esta registrado
A9: 131233465 | B9: 1 | C9: 2 | D9: =IF(C9=1,Leyenda!$C$3,IF(C9=2,Leyenda!$C$4,IF(C9=3,Leyenda!$C$5,IF(C9=4,Leyenda!$C$6,IF(C9=5,Leyenda!$C$7,IF(C9=6,Leyenda!$C$8,IF(C9=7,Leyenda!$C$9,IF(C9=8,Leyenda!$C$10," "))))))))&IF(C9=9,Leyenda!$C$11,IF(C9=10,Leyenda!$C$12,IF(C9=11,Leyenda!$C$13,IF(C9=12,Leyenda!D74," ")))) -> GASTOS POR TRABAJOS, SUMINISTROS Y SERVICIOS | E9: B0100045296 | F9: 45701 | G9: =TEXT(F9,"MMMM") -> febrero | H9: 13 | I9: =TEXT(gastos[[#This Row],[Fecha]],"DDDD") -> jueves | J9: =DATE(YEAR(F9),MONTH(F9),H9) -> 45701 | K9: Ernesto | L9: Café | M9: 500 | N9: 0 | O9: =SUM(M9:N9) -> 500 | P9: 90 | Q9: 0 | R9: 50 | S9: Tarjata de credito | T9: =IFERROR(VLOOKUP($A9,Tabla3[#All],2,0),"no esta registrado") -> NOCCIOLA FOOD HALL SRL
A10: 130794987 | B10: 1 | C10: 4 | D10: =IF(C10=1,Leyenda!$C$3,IF(C10=2,Leyenda!$C$4,IF(C10=3,Leyenda!$C$5,IF(C10=4,Leyenda!$C$6,IF(C10=5,Leyenda!$C$7,IF(C10=6,Leyenda!$C$8,IF(C10=7,Leyenda!$C$9,IF(C10=8,Leyenda!$C$10," "))))))))&IF(C10=9,Leyenda!$C$11,IF(C10=10,Leyenda!$C$12,IF(C10=11,Leyenda!$C$13,IF(C10=12,Leyenda!D74," ")))) -> GASTOS DE ACTIVOS FIJO | E10: B0101396124 | F10: 45763 | G10: =TEXT(F10,"MMMM") -> abril | H10: 16 | I10: =TEXT(gastos[[#This Row],[Fecha]],"DDDD") -> miércoles | J10: =DATE(YEAR(F10),MONTH(F10),H10) -> 45763 | K10: Ernesto | L10: Diesel | M10: 4662 | N10: 0 | O10: =SUM(M10:N10) -> 4662 | P10: 0 | Q10: 0 | R10: 0 | S10: Tarjata de credito | T10: =IFERROR(VLOOKUP($A10,Tabla3[#All],2,0),"no esta registrado") -> Strata, S.R.L.
A11: 130794987 | B11: 1 | C11: 4 | D11: =IF(C11=1,Leyenda!$C$3,IF(C11=2,Leyenda!$C$4,IF(C11=3,Leyenda!$C$5,IF(C11=4,Leyenda!$C$6,IF(C11=5,Leyenda!$C$7,IF(C11=6,Leyenda!$C$8,IF(C11=7,Leyenda!$C$9,IF(C11=8,Leyenda!$C$10," "))))))))&IF(C11=9,Leyenda!$C$11,IF(C11=10,Leyenda!$C$12,IF(C11=11,Leyenda!$C$13,IF(C11=12,Leyenda!D74," ")))) -> GASTOS DE ACTIVOS FIJO | E11: B0101358304 | F11: 45675 | G11: =TEXT(F11,"MMMM") -> enero | H11: 18 | I11: =TEXT(gastos[[#This Row],[Fecha]],"DDDD") -> sábado | J11: =DATE(YEAR(F11),MONTH(F11),H11) -> 45675 | K11: Ernesto | L11: Diesel | M11: 4702 | N11: 0 | O11: =SUM(M11:N11) -> 4702 | P11: 0 | Q11: 0 | R11: 0 | S11: Tarjata de credito | T11: =IFERROR(VLOOKUP($A11,Tabla3[#All],2,0),"no esta registrado") -> Strata, S.R.L.
A12: 130794987 | B12: 1 | C12: 4 | D12: =IF(C12=1,Leyenda!$C$3,IF(C12=2,Leyenda!$C$4,IF(C12=3,Leyenda!$C$5,IF(C12=4,Leyenda!$C$6,IF(C12=5,Leyenda!$C$7,IF(C12=6,Leyenda!$C$8,IF(C12=7,Leyenda!$C$9,IF(C12=8,Leyenda!$C$10," "))))))))&IF(C12=9,Leyenda!$C$11,IF(C12=10,Leyenda!$C$12,IF(C12=11,Leyenda!$C$13,IF(C12=12,Leyenda!D74," ")))) -> GASTOS DE ACTIVOS FIJO | E12: B0101384645 | F12: 45738 | G12: =TEXT(F12,"MMMM") -> marzo | H12: 22 | I12: =TEXT(gastos[[#This Row],[Fecha]],"DDDD") -> sábado | J12: =DATE(YEAR(F12),MONTH(F12),H12) -> 45738 | K12: Ernesto | L12: Diesel | M12: 4822.9 | N12: 0 | O12: =SUM(M12:N12) -> 4822.9 | P12: 0 | Q12: 0 | R12: 0 | S12: Tarjata de credito | T12: =IFERROR(VLOOKUP($A12,Tabla3[#All],2,0),"no esta registrado") -> Strata, S.R.L.
A13: 130794987 | B13: 1 | C13: 4 | D13: =IF(C13=1,Leyenda!$C$3,IF(C13=2,Leyenda!$C$4,IF(C13=3,Leyenda!$C$5,IF(C13=4,Leyenda!$C$6,IF(C13=5,Leyenda!$C$7,IF(C13=6,Leyenda!$C$8,IF(C13=7,Leyenda!$C$9,IF(C13=8,Leyenda!$C$10," "))))))))&IF(C13=9,Leyenda!$C$11,IF(C13=10,Leyenda!$C$12,IF(C13=11,Leyenda!$C$13,IF(C13=12,Leyenda!D74," ")))) -> GASTOS DE ACTIVOS FIJO | E13: B0101377121 | F13: 45723 | G13: =TEXT(F13,"MMMM") -> marzo | H13: 7 | I13: =TEXT(gastos[[#This Row],[Fecha]],"DDDD") -> viernes | J13: =DATE(YEAR(F13),MONTH(F13),H13) -> 45723 | K13: Ernesto | L13: Diesel | M13: 4867 | N13: 0 | O13: =SUM(M13:N13) -> 4867 | P13: 0 | Q13: 0 | R13: 0 | S13: Tarjata de credito | T13: =IFERROR(VLOOKUP($A13,Tabla3[#All],2,0),"no esta registrado") -> Strata, S.R.L.
A14: 101008172 | B14: 1 | C14: 4 | D14: =IF(C14=1,Leyenda!$C$3,IF(C14=2,Leyenda!$C$4,IF(C14=3,Leyenda!$C$5,IF(C14=4,Leyenda!$C$6,IF(C14=5,Leyenda!$C$7,IF(C14=6,Leyenda!$C$8,IF(C14=7,Leyenda!$C$9,IF(C14=8,Leyenda!$C$10," "))))))))&IF(C14=9,Leyenda!$C$11,IF(C14=10,Leyenda!$C$12,IF(C14=11,Leyenda!$C$13,IF(C14=12,Leyenda!D74," ")))) -> GASTOS DE ACTIVOS FIJO | E14: B01018657107 | F14: 45692 | G14: =TEXT(F14,"MMMM") -> febrero | H14: 4 | I14: =TEXT(gastos[[#This Row],[Fecha]],"DDDD") -> martes | J14: =DATE(YEAR(F14),MONTH(F14),H14) -> 45692 | K14: Casa | L14: Gas Domestico | M14: 1458 | N14: 0 | O14: =SUM(M14:N14) -> 1458 | P14: 0 | Q14: 0 | R14: 0 | S14: Tarjata de credito | T14: =IFERROR(VLOOKUP($A14,Tabla3[#All],2,0),"no esta registrado") -> Isla Dominicana de Petroleo, Corp.
A15: 130794987 | B15: 1 | C15: 4 | D15: =IF(C15=1,Leyenda!$C$3,IF(C15=2,Leyenda!$C$4,IF(C15=3,Leyenda!$C$5,IF(C15=4,Leyenda!$C$6,IF(C15=5,Leyenda!$C$7,IF(C15=6,Leyenda!$C$8,IF(C15=7,Leyenda!$C$9,IF(C15=8,Leyenda!$C$10," "))))))))&IF(C15=9,Leyenda!$C$11,IF(C15=10,Leyenda!$C$12,IF(C15=11,Leyenda!$C$13,IF(C15=12,Leyenda!D74," ")))) -> GASTOS DE ACTIVOS FIJO | E15: B0101369091 | F15: 45700 | G15: =TEXT(F15,"MMMM") -> febrero | H15: 12 | I15: =TEXT(gastos[[#This Row],[Fecha]],"DDDD") -> miércoles | J15: =DATE(YEAR(F15),MONTH(F15),H15) -> 45700 | K15: Ernesto | L15: Diesel | M15: 4722 | N15: 0 | O15: =SUM(M15:N15) -> 4722 | P15: 0 | Q15: 0 | R15: 0 | S15: Tarjata de credito | T15: =IFERROR(VLOOKUP($A15,Tabla3[#All],2,0),"no esta registrado") -> Strata, S.R.L.
A16: 101025794 | B16: 1 | C16: 4 | D16: =IF(C16=1,Leyenda!$C$3,IF(C16=2,Leyenda!$C$4,IF(C16=3,Leyenda!$C$5,IF(C16=4,Leyenda!$C$6,IF(C16=5,Leyenda!$C$7,IF(C16=6,Leyenda!$C$8,IF(C16=7,Leyenda!$C$9,IF(C16=8,Leyenda!$C$10," "))))))))&IF(C16=9,Leyenda!$C$11,IF(C16=10,Leyenda!$C$12,IF(C16=11,Leyenda!$C$13,IF(C16=12,Leyenda!D74," ")))) -> GASTOS DE ACTIVOS FIJO | E16: B0100145993 | F16: 45728 | G16: =TEXT(F16,"MMMM") -> marzo | H16: 12 | I16: =TEXT(gastos[[#This Row],[Fecha]],"DDDD") -> miércoles | J16: =DATE(YEAR(F16),MONTH(F16),H16) -> 45728 | K16: Casa | L16: Gas Domestico | M16: 1578 | N16: 0 | O16: =SUM(M16:N16) -> 1578 | P16: 0 | Q16: 0 | R16: 0 | S16: Tarjata de credito | T16: =IFERROR(VLOOKUP($A16,Tabla3[#All],2,0),"no esta registrado") -> Envasadora Gas Caribe Principal
A17: 130794987 | B17: 1 | C17: 4 | D17: =IF(C17=1,Leyenda!$C$3,IF(C17=2,Leyenda!$C$4,IF(C17=3,Leyenda!$C$5,IF(C17=4,Leyenda!$C$6,IF(C17=5,Leyenda!$C$7,IF(C17=6,Leyenda!$C$8,IF(C17=7,Leyenda!$C$9,IF(C17=8,Leyenda!$C$10," "))))))))&IF(C17=9,Leyenda!$C$11,IF(C17=10,Leyenda!$C$12,IF(C17=11,Leyenda!$C$13,IF(C17=12,Leyenda!D74," ")))) -> GASTOS DE ACTIVOS FIJO | E17: B0101193605 | F17: 45316 | G17: =TEXT(F17,"MMMM") -> enero | H17: 25 | I17: =TEXT(gastos[[#This Row],[Fecha]],"DDDD") -> jueves | J17: =DATE(YEAR(F17),MONTH(F17),H17) -> 45316 | M17: 0 | N17: 3560 | O17: =SUM(M17:N17) -> 3560 | P17: 0 | Q17: 0 | R17: 0 | S17: 0 | T17: =VLOOKUP($A17,Tabla3[#All],2,0) -> Strata, S.R.L.
A18: 130794987 | B18: 1 | C18: 4 | D18: =IF(C18=1,Leyenda!$C$3,IF(C18=2,Leyenda!$C$4,IF(C18=3,Leyenda!$C$5,IF(C18=4,Leyenda!$C$6,IF(C18=5,Leyenda!$C$7,IF(C18=6,Leyenda!$C$8,IF(C18=7,Leyenda!$C$9,IF(C18=8,Leyenda!$C$10," "))))))))&IF(C18=9,Leyenda!$C$11,IF(C18=10,Leyenda!$C$12,IF(C18=11,Leyenda!$C$13,IF(C18=12,Leyenda!D75," ")))) -> GASTOS DE ACTIVOS FIJO | E18: B0101186499 | F18: 45301 | G18: =TEXT(F18,"MMMM") -> enero | H18: 10 | I18: =TEXT(gastos[[#This Row],[Fecha]],"DDDD") -> miércoles | J18: =DATE(YEAR(F18),MONTH(F18),H18) -> 45301 | M18: 0 | N18: 3500 | O18: =SUM(M18:N18) -> 3500 | P18: 0 | Q18: 0 | R18: 0 | S18: 0 | T18: =VLOOKUP($A18,Tabla3[#All],2,0) -> Strata, S.R.L.
A19: 130794987 | B19: 1 | C19: 4 | D19: =IF(C19=1,Leyenda!$C$3,IF(C19=2,Leyenda!$C$4,IF(C19=3,Leyenda!$C$5,IF(C19=4,Leyenda!$C$6,IF(C19=5,Leyenda!$C$7,IF(C19=6,Leyenda!$C$8,IF(C19=7,Leyenda!$C$9,IF(C19=8,Leyenda!$C$10," "))))))))&IF(C19=9,Leyenda!$C$11,IF(C19=10,Leyenda!$C$12,IF(C19=11,Leyenda!$C$13,IF(C19=12,Leyenda!D76," ")))) -> GASTOS DE ACTIVOS FIJO | E19: B0101205083 | F19: 45292 | G19: =TEXT(F19,"MMMM") -> enero | H19: 1 | I19: =TEXT(gastos[[#This Row],[Fecha]],"DDDD") -> lunes | J19: =DATE(YEAR(F19),MONTH(F19),H19) -> 45292 | M19: 0 | N19: 3384 | O19: =SUM(M19:N19) -> 3384 | P19: 0 | Q19: 0 | R19: 0 | S19: 0 | T19: =VLOOKUP($A19,Tabla3[#All],2,0) -> Strata, S.R.L.
A20: 00101352929 | B20: 2 | C20: 2 | D20: =IF(C20=1,Leyenda!$C$3,IF(C20=2,Leyenda!$C$4,IF(C20=3,Leyenda!$C$5,IF(C20=4,Leyenda!$C$6,IF(C20=5,Leyenda!$C$7,IF(C20=6,Leyenda!$C$8,IF(C20=7,Leyenda!$C$9,IF(C20=8,Leyenda!$C$10," "))))))))&IF(C20=9,Leyenda!$C$11,IF(C20=10,Leyenda!$C$12,IF(C20=11,Leyenda!$C$13,IF(C20=12,Leyenda!D77," ")))) -> GASTOS POR TRABAJOS, SUMINISTROS Y SERVICIOS | E20: B0100038002 | F20: 45307 | G20: =TEXT(F20,"MMMM") -> enero | H20: 16 | I20: =TEXT(gastos[[#This Row],[Fecha]],"DDDD") -> martes | J20: =DATE(YEAR(F20),MONTH(F20),H20) -> 45307 | M20: 0 | N20: =1500-228.81 -> 1271.19 | O20: =SUM(M20:N20) -> 1271.19 | P20: 228.81 | Q20: 0 | R20: 0 | S20: 0 | T20: =IFERROR(VLOOKUP($A20,Tabla3[#All],2,0),"no esta registrado") -> no esta registrado
A21: 131153666 | B21: 1 | C21: 2 | D21: =IF(C21=1,Leyenda!$C$3,IF(C21=2,Leyenda!$C$4,IF(C21=3,Leyenda!$C$5,IF(C21=4,Leyenda!$C$6,IF(C21=5,Leyenda!$C$7,IF(C21=6,Leyenda!$C$8,IF(C21=7,Leyenda!$C$9,IF(C21=8,Leyenda!$C$10," "))))))))&IF(C21=9,Leyenda!$C$11,IF(C21=10,Leyenda!$C$12,IF(C21=11,Leyenda!$C$13,IF(C21=12,Leyenda!D78," ")))) -> GASTOS POR TRABAJOS, SUMINISTROS Y SERVICIOS | E21: B0100004392 | F21: 45295 | G21: =TEXT(F21,"MMMM") -> enero | H21: 4 | I21: =TEXT(gastos[[#This Row],[Fecha]],"DDDD") -> jueves | J21: =DATE(YEAR(F21),MONTH(F21),H21) -> 45295 | M21: 0 | N21: 622.89 | O21: =SUM(M21:N21) -> 622.89 | P21: 112.13 | Q21: 0 | R21: 0 | S21: 0 | T21: =IFERROR(VLOOKUP($A21,Tabla3[#All],2,0),"no esta registrado") -> Grupo VARNET
A22: 101863528 | B22: 1 | C22: 2 | D22: =IF(C22=1,Leyenda!$C$3,IF(C22=2,Leyenda!$C$4,IF(C22=3,Leyenda!$C$5,IF(C22=4,Leyenda!$C$6,IF(C22=5,Leyenda!$C$7,IF(C22=6,Leyenda!$C$8,IF(C22=7,Leyenda!$C$9,IF(C22=8,Leyenda!$C$10," "))))))))&IF(C22=9,Leyenda!$C$11,IF(C22=10,Leyenda!$C$12,IF(C22=11,Leyenda!$C$13,IF(C22=12,Leyenda!D79," ")))) -> GASTOS POR TRABAJOS, SUMINISTROS Y SERVICIOS | E22: E310000002110 | F22: 45305 | G22: =TEXT(F22,"MMMM") -> enero | H22: 14 | I22: =TEXT(gastos[[#This Row],[Fecha]],"DDDD") -> domingo | J22: =DATE(YEAR(F22),MONTH(F22),H22) -> 45305 | M22: 0 | N22: 794.49 | O22: =SUM(M22:N22) -> 794.49 | P22: 143.01 | Q22: 0 | R22: 0 | S22: 0 | T22: =IFERROR(VLOOKUP($A22,Tabla3[#All],2,0),"no esta registrado") -> Payless Shoesource
A23: 101602465 | B23: 1 | C23: 2 | D23: =IF(C23=1,Leyenda!$C$3,IF(C23=2,Leyenda!$C$4,IF(C23=3,Leyenda!$C$5,IF(C23=4,Leyenda!$C$6,IF(C23=5,Leyenda!$C$7,IF(C23=6,Leyenda!$C$8,IF(C23=7,Leyenda!$C$9,IF(C23=8,Leyenda!$C$10," "))))))))&IF(C23=9,Leyenda!$C$11,IF(C23=10,Leyenda!$C$12,IF(C23=11,Leyenda!$C$13,IF(C23=12,Leyenda!D80," ")))) -> GASTOS POR TRABAJOS, SUMINISTROS Y SERVICIOS | E23: E310003929628 | F23: 45297 | G23: =TEXT(F23,"MMMM") -> enero | H23: 6 | I23: =TEXT(gastos[[#This Row],[Fecha]],"DDDD") -> sábado | J23: =DATE(YEAR(F23),MONTH(F23),H23) -> 45297 | M23: 0 | N23: =1712-149.35 -> 1562.65 | O23: =SUM(M23:N23) -> 1562.65 | P23: 149.35 | Q23: 0 | R23: 0 | S23: 0 | T23: =IFERROR(VLOOKUP($A23,Tabla3[#All],2,0),"no esta registrado") -> Bravo, S.A.//Supermercados Bravo
A24: 101602465 | B24: 1 | C24: 2 | D24: =IF(C24=1,Leyenda!$C$3,IF(C24=2,Leyenda!$C$4,IF(C24=3,Leyenda!$C$5,IF(C24=4,Leyenda!$C$6,IF(C24=5,Leyenda!$C$7,IF(C24=6,Leyenda!$C$8,IF(C24=7,Leyenda!$C$9,IF(C24=8,Leyenda!$C$10," "))))))))&IF(C24=9,Leyenda!$C$11,IF(C24=10,Leyenda!$C$12,IF(C24=11,Leyenda!$C$13,IF(C24=12,Leyenda!D81," ")))) -> GASTOS POR TRABAJOS, SUMINISTROS Y SERVICIOS | E24: E310003931395 | F24: 45304 | G24: =TEXT(F24,"MMMM") -> enero | H24: 13 | I24: =TEXT(gastos[[#This Row],[Fecha]],"DDDD") -> sábado | J24: =DATE(YEAR(F24),MONTH(F24),H24) -> 45304 | M24: 0 | N24: =14132-1135.17 -> 12996.83 | O24: =SUM(M24:N24) -> 12996.83 | P24: 1135.17 | Q24: 0 | R24: 0 | S24: 0 | T24: =IFERROR(VLOOKUP($A24,Tabla3[#All],2,0),"no esta registrado") -> Bravo, S.A.//Supermercados Bravo
A25: 101602465 | B25: 1 | C25: 2 | D25: =IF(C25=1,Leyenda!$C$3,IF(C25=2,Leyenda!$C$4,IF(C25=3,Leyenda!$C$5,IF(C25=4,Leyenda!$C$6,IF(C25=5,Leyenda!$C$7,IF(C25=6,Leyenda!$C$8,IF(C25=7,Leyenda!$C$9,IF(C25=8,Leyenda!$C$10," "))))))))&IF(C25=9,Leyenda!$C$11,IF(C25=10,Leyenda!$C$12,IF(C25=11,Leyenda!$C$13,IF(C25=12,Leyenda!D82," ")))) -> GASTOS POR TRABAJOS, SUMINISTROS Y SERVICIOS | E25: E310003932338 | F25: 45308 | G25: =TEXT(F25,"MMMM") -> enero | H25: 17 | I25: =TEXT(gastos[[#This Row],[Fecha]],"DDDD") -> miércoles | J25: =DATE(YEAR(F25),MONTH(F25),H25) -> 45308 | M25: 0 | N25: =1725-201.67 -> 1523.33 | O25: =SUM(M25:N25) -> 1523.33 | P25: 201.67 | Q25: 0 | R25: 0 | S25: 0 | T25: =IFERROR(VLOOKUP($A25,Tabla3[#All],2,0),"no esta registrado") -> Bravo, S.A.//Supermercados Bravo
A26: 101019921 | B26: 1 | C26: 2 | D26: =IF(C26=1,Leyenda!$C$3,IF(C26=2,Leyenda!$C$4,IF(C26=3,Leyenda!$C$5,IF(C26=4,Leyenda!$C$6,IF(C26=5,Leyenda!$C$7,IF(C26=6,Leyenda!$C$8,IF(C26=7,Leyenda!$C$9,IF(C26=8,Leyenda!$C$10," "))))))))&IF(C26=9,Leyenda!$C$11,IF(C26=10,Leyenda!$C$12,IF(C26=11,Leyenda!$C$13,IF(C26=12,Leyenda!D83," ")))) -> GASTOS POR TRABAJOS, SUMINISTROS Y SERVICIOS | E26: B0114461355 | F26: 45311 | G26: =TEXT(F26,"MMMM") -> enero | H26: 20 | I26: =TEXT(gastos[[#This Row],[Fecha]],"DDDD") -> sábado | J26: =DATE(YEAR(F26),MONTH(F26),H26) -> 45311 | M26: 0 | N26: =2059.95-314.23 -> 1745.72 | O26: =SUM(M26:N26) -> 1745.72 | P26: 314.23 | Q26: 0 | R26: 0 | S26: 0 | T26: =IFERROR(VLOOKUP($A26,Tabla3[#All],2,0),"no esta registrado") -> Centro Cuesta Nacional S.A.S.//Supermercados Nacional//Casa Cuesta//Ferretería Cuesta//JUMBO//Bebemundo
A27: 101602465 | B27: 1 | C27: 2 | D27: =IF(C27=1,Leyenda!$C$3,IF(C27=2,Leyenda!$C$4,IF(C27=3,Leyenda!$C$5,IF(C27=4,Leyenda!$C$6,IF(C27=5,Leyenda!$C$7,IF(C27=6,Leyenda!$C$8,IF(C27=7,Leyenda!$C$9,IF(C27=8,Leyenda!$C$10," "))))))))&IF(C27=9,Leyenda!$C$11,IF(C27=10,Leyenda!$C$12,IF(C27=11,Leyenda!$C$13,IF(C27=12,Leyenda!D84," ")))) -> GASTOS POR TRABAJOS, SUMINISTROS Y SERVICIOS | E27: E310003528970 | F27: 45293 | G27: =TEXT(F27,"MMMM") -> enero | H27: 2 | I27: =TEXT(gastos[[#This Row],[Fecha]],"DDDD") -> martes | J27: =DATE(YEAR(F27),MONTH(F27),H27) -> 45293 | M27: 0 | N27: =12866-1080.27 -> 11785.73 | O27: =SUM(M27:N27) -> 11785.73 | P27: 1080.27 | Q27: 0 | R27: 0 | S27: 0 | T27: =IFERROR(VLOOKUP($A27,Tabla3[#All],2,0),"no esta registrado") -> Bravo, S.A.//Supermercados Bravo
A28: 130196796 | B28: 1 | C28: 2 | D28: =IF(C28=1,Leyenda!$C$3,IF(C28=2,Leyenda!$C$4,IF(C28=3,Leyenda!$C$5,IF(C28=4,Leyenda!$C$6,IF(C28=5,Leyenda!$C$7,IF(C28=6,Leyenda!$C$8,IF(C28=7,Leyenda!$C$9,IF(C28=8,Leyenda!$C$10," "))))))))&IF(C28=9,Leyenda!$C$11,IF(C28=10,Leyenda!$C$12,IF(C28=11,Leyenda!$C$13,IF(C28=12,Leyenda!D85," ")))) -> GASTOS POR TRABAJOS, SUMINISTROS Y SERVICIOS | E28: B0100053568 | F28: 45311 | G28: =TEXT(F28,"MMMM") -> enero | H28: 20 | I28: =TEXT(gastos[[#This Row],[Fecha]],"DDDD") -> sábado | J28: =DATE(YEAR(F28),MONTH(F28),H28) -> 45311 | M28: 2876 | N28: 0 | O28: =SUM(M28:N28) -> 2876 | P28: 0 | Q28: 0 | R28: 0 | S28: 0 | T28: =IFERROR(VLOOKUP($A28,Tabla3[#All],2,0),"no esta registrado") -> ACADEMIA EUROPEA
A29: 130196796 | B29: 1 | C29: 2 | D29: =IF(C29=1,Leyenda!$C$3,IF(C29=2,Leyenda!$C$4,IF(C29=3,Leyenda!$C$5,IF(C29=4,Leyenda!$C$6,IF(C29=5,Leyenda!$C$7,IF(C29=6,Leyenda!$C$8,IF(C29=7,Leyenda!$C$9,IF(C29=8,Leyenda!$C$10," "))))))))&IF(C29=9,Leyenda!$C$11,IF(C29=10,Leyenda!$C$12,IF(C29=11,Leyenda!$C$13,IF(C29=12,Leyenda!D86," ")))) -> GASTOS POR TRABAJOS, SUMINISTROS Y SERVICIOS | E29: B0100053388 | F29: 45303 | G29: =TEXT(F29,"MMMM") -> enero | H29: 12 | I29: =TEXT(gastos[[#This Row],[Fecha]],"DDDD") -> viernes | J29: =DATE(YEAR(F29),MONTH(F29),H29) -> 45303 | M29: 3190 | N29: 0 | O29: =SUM(M29:N29) -> 3190 | P29: 0 | Q29: 0 | R29: 0 | S29: 0 | T29: =IFERROR(VLOOKUP($A29,Tabla3[#All],2,0),"no esta registrado") -> ACADEMIA EUROPEA
A30: 130857865 | B30: 1 | C30: 7 | D30: =IF(C30=1,Leyenda!$C$3,IF(C30=2,Leyenda!$C$4,IF(C30=3,Leyenda!$C$5,IF(C30=4,Leyenda!$C$6,IF(C30=5,Leyenda!$C$7,IF(C30=6,Leyenda!$C$8,IF(C30=7,Leyenda!$C$9,IF(C30=8,Leyenda!$C$10," "))))))))&IF(C30=9,Leyenda!$C$11,IF(C30=10,Leyenda!$C$12,IF(C30=11,Leyenda!$C$13,IF(C30=12,Leyenda!D87," ")))) -> GASTOS FINANCIEROS | E30: B0100056091 | F30: 45292 | G30: =TEXT(F30,"MMMM") -> enero | H30: 1 | I30: =TEXT(gastos[[#This Row],[Fecha]],"DDDD") -> lunes | J30: =DATE(YEAR(F30),MONTH(F30),H30) -> 45292 | M30: 0 | N30: 1309.32 | O30: =SUM(M30:N30) -> 1309.32 | P30: 235.68 | Q30: 0 | R30: 0 | S30: 0 | T30: =IFERROR(VLOOKUP($A30,Tabla3[#All],2,0),"no esta registrado") -> no esta registrado
A31: 101602465 | B31: 1 | C31: 2 | D31: =IF(C31=1,Leyenda!$C$3,IF(C31=2,Leyenda!$C$4,IF(C31=3,Leyenda!$C$5,IF(C31=4,Leyenda!$C$6,IF(C31=5,Leyenda!$C$7,IF(C31=6,Leyenda!$C$8,IF(C31=7,Leyenda!$C$9,IF(C31=8,Leyenda!$C$10," "))))))))&IF(C31=9,Leyenda!$C$11,IF(C31=10,Leyenda!$C$12,IF(C31=11,Leyenda!$C$13,IF(C31=12,Leyenda!D88," ")))) -> GASTOS POR TRABAJOS, SUMINISTROS Y SERVICIOS | E31: E310003956081 | F31: 45315 | G31: =TEXT(F31,"MMMM") -> enero | H31: 24 | I31: =TEXT(gastos[[#This Row],[Fecha]],"DDDD") -> miércoles | J31: =DATE(YEAR(F31),MONTH(F31),H31) -> 45315 | M31: 1490 | N31: 0 | O31: =SUM(M31:N31) -> 1490 | P31: 0 | Q31: 0 | R31: 0 | S31: 0 | T31: =IFERROR(VLOOKUP($A31,Tabla3[#All],2,0),"no esta registrado") -> Bravo, S.A.//Supermercados Bravo
A32: 131619046 | B32: 1 | C32: 2 | D32: =IF(C32=1,Leyenda!$C$3,IF(C32=2,Leyenda!$C$4,IF(C32=3,Leyenda!$C$5,IF(C32=4,Leyenda!$C$6,IF(C32=5,Leyenda!$C$7,IF(C32=6,Leyenda!$C$8,IF(C32=7,Leyenda!$C$9,IF(C32=8,Leyenda!$C$10," "))))))))&IF(C32=9,Leyenda!$C$11,IF(C32=10,Leyenda!$C$12,IF(C32=11,Leyenda!$C$13,IF(C32=12,Leyenda!D89," ")))) -> GASTOS POR TRABAJOS, SUMINISTROS Y SERVICIOS | E32: B0100001472 | F32: 45308 | G32: =TEXT(F32,"MMMM") -> enero | H32: 17 | I32: =TEXT(gastos[[#This Row],[Fecha]],"DDDD") -> miércoles | J32: =DATE(YEAR(F32),MONTH(F32),H32) -> 45308 | M32: 0 | N32: 1072.03 | O32: =SUM(M32:N32) -> 1072.03 | P32: 192.97 | Q32: 0 | R32: 0 | S32: 0 | T32: =IFERROR(VLOOKUP($A32,Tabla3[#All],2,0),"no esta registrado") -> no esta registrado
A33: 101876077 | B33: 1 | C33: 2 | D33: =IF(C33=1,Leyenda!$C$3,IF(C33=2,Leyenda!$C$4,IF(C33=3,Leyenda!$C$5,IF(C33=4,Leyenda!$C$6,IF(C33=5,Leyenda!$C$7,IF(C33=6,Leyenda!$C$8,IF(C33=7,Leyenda!$C$9,IF(C33=8,Leyenda!$C$10," "))))))))&IF(C33=9,Leyenda!$C$11,IF(C33=10,Leyenda!$C$12,IF(C33=11,Leyenda!$C$13,IF(C33=12,Leyenda!D90," ")))) -> GASTOS POR TRABAJOS, SUMINISTROS Y SERVICIOS | E33: B0100003560 | F33: 45314 | G33: =TEXT(F33,"MMMM") -> enero | H33: 23 | I33: =TEXT(gastos[[#This Row],[Fecha]],"DDDD") -> martes | J33: =DATE(YEAR(F33),MONTH(F33),H33) -> 45314 | M33: 0 | N33: 8474.58 | O33: =SUM(M33:N33) -> 8474.58 | P33: 1525.42 | Q33: 0 | R33: 0 | S33: 0 | T33: =IFERROR(VLOOKUP($A33,Tabla3[#All],2,0),"no esta registrado") -> no esta registrado
A34: 131156398 | B34: 1 | C34: 2 | D34: =IF(C34=1,Leyenda!$C$3,IF(C34=2,Leyenda!$C$4,IF(C34=3,Leyenda!$C$5,IF(C34=4,Leyenda!$C$6,IF(C34=5,Leyenda!$C$7,IF(C34=6,Leyenda!$C$8,IF(C34=7,Leyenda!$C$9,IF(C34=8,Leyenda!$C$10," "))))))))&IF(C34=9,Leyenda!$C$11,IF(C34=10,Leyenda!$C$12,IF(C34=11,Leyenda!$C$13,IF(C34=12,Leyenda!D91," ")))) -> GASTOS POR TRABAJOS, SUMINISTROS Y SERVICIOS | E34: B0100033027 | F34: 45299 | G34: =TEXT(F34,"MMMM") -> enero | H34: 8 | I34: =TEXT(gastos[[#This Row],[Fecha]],"DDDD") -> lunes | J34: =DATE(YEAR(F34),MONTH(F34),H34) -> 45299 | M34: 0 | N34: 250.16 | O34: =SUM(M34:N34) -> 250.16 | P34: 25.28 | Q34: 0 | R34: 0 | S34: 0 | T34: =IFERROR(VLOOKUP($A34,Tabla3[#All],2,0),"no esta registrado") -> no esta registrado
A35: 430030341 | B35: 1 | C35: 2 | D35: =IF(C35=1,Leyenda!$C$3,IF(C35=2,Leyenda!$C$4,IF(C35=3,Leyenda!$C$5,IF(C35=4,Leyenda!$C$6,IF(C35=5,Leyenda!$C$7,IF(C35=6,Leyenda!$C$8,IF(C35=7,Leyenda!$C$9,IF(C35=8,Leyenda!$C$10," "))))))))&IF(C35=9,Leyenda!$C$11,IF(C35=10,Leyenda!$C$12,IF(C35=11,Leyenda!$C$13,IF(C35=12,Leyenda!D92," ")))) -> GASTOS POR TRABAJOS, SUMINISTROS Y SERVICIOS | E35: B0100012571 | F35: 45300 | G35: =TEXT(F35,"MMMM") -> enero | H35: 9 | I35: =TEXT(gastos[[#This Row],[Fecha]],"DDDD") -> martes | J35: =DATE(YEAR(F35),MONTH(F35),H35) -> 45300 | M35: 7100 | N35: 0 | O35: =SUM(M35:N35) -> 7100 | P35: 0 | Q35: 0 | R35: 0 | S35: 0 | T35: =IFERROR(VLOOKUP($A35,Tabla3[#All],2,0),"no esta registrado") -> COLEGIO SANTA ROSA DE LIMA
A36: 430030341 | B36: 1 | C36: 2 | D36: =IF(C36=1,Leyenda!$C$3,IF(C36=2,Leyenda!$C$4,IF(C36=3,Leyenda!$C$5,IF(C36=4,Leyenda!$C$6,IF(C36=5,Leyenda!$C$7,IF(C36=6,Leyenda!$C$8,IF(C36=7,Leyenda!$C$9,IF(C36=8,Leyenda!$C$10," "))))))))&IF(C36=9,Leyenda!$C$11,IF(C36=10,Leyenda!$C$12,IF(C36=11,Leyenda!$C$13,IF(C36=12,Leyenda!D93," ")))) -> GASTOS POR TRABAJOS, SUMINISTROS Y SERVICIOS | E36: B0100012572 | F36: 45300 | G36: =TEXT(F36,"MMMM") -> enero | H36: 9 | I36: =TEXT(gastos[[#This Row],[Fecha]],"DDDD") -> martes | J36: =DATE(YEAR(F36),MONTH(F36),H36) -> 45300 | M36: 6800 | N36: 0 | O36: =SUM(M36:N36) -> 6800 | P36: 0 | Q36: 0 | R36: 0 | S36: 0 | T36: =IFERROR(VLOOKUP($A36,Tabla3[#All],2,0),"no esta registrado") -> COLEGIO SANTA ROSA DE LIMA
